<?xml version="1.0" encoding="utf-8"?>
<!-- =================================================================================== -->
<!-- |    This document was autogenerated by xacro from Z550.xacro                     | -->
<!-- |    EDITING THIS FILE BY HAND IS NOT RECOMMENDED                                 | -->
<!-- =================================================================================== -->
<robot name="example">
  <!-- Base link -->
  <link name="base_link">
    <inertial>
      <origin xyz="0 0 0"/>
      <mass value="1.5"/>
      <inertia ixx="0.029125" ixy="0" ixz="0" iyy="0.029125" iyz="0" izz="0.055225"/>
    </inertial>
    <collision name="base_link_inertia_collision_4">
      <geometry>
        <cylinder length="0.005" radius="0.47"/>
      </geometry>
    </collision>
    <visual name="base_link_inertia_visual_4">
      <geometry>
        <mesh filename="/home/byy/catkin_ws/src/livox_laser_simulation/meshes/ZD550_motors_amend.dae" scale="1 1 1"/>
      </geometry>
    </visual>
  </link>
  <!-- IMU link -->
  <link name="imu_link">
    <inertial>
      <origin xyz="0 0 0"/>
      <mass value="1.5"/>
      <inertia ixx="1e-05" ixy="0" ixz="0" iyy="1e-05" iyz="0" izz="1e-05"/>
    </inertial>
  </link>
  <joint name="imu_joint" type="revolute">
    <parent link="base_link"/>
    <child link="imu_link"/>
    <origin rpy="0 0 0" xyz="0 0 0"/>
    <axis xyz="1 0 0"/>
    <limit effort="0" lower="0" upper="0" velocity="0"/>
    <dynamics damping="0" friction="0"/>
  </joint>
  <link name="rotor_0">
    <inertial>
      <origin xyz="0 0 0"/>
      <mass value="1.5"/>
      <inertia ixx="9.75e-07" ixy="0" ixz="0" iyy="0.000273104" iyz="0" izz="0.000274004"/>
    </inertial>
    <collision name="rotor_0_collision">
      <geometry>
        <cylinder length="0.005" radius="0.128"/>
      </geometry>
    </collision>
    <visual name="rotor_0_visual">
      <geometry>
        <mesh filename="/home/byy/catkin_ws/src/livox_laser_simulation/meshes/iris_prop_ccw.dae" scale="1 1 1"/>
      </geometry>
    </visual>
  </link>
  <joint name="rotor_0_joint" type="revolute">
    <parent link="base_link"/>
    <child link="rotor_0"/>
    <origin rpy="0 0 0" xyz="0.2 -0.2 0.34"/>
    <axis xyz="0 0 1"/>
    <limit effort="0" lower="-1e+16" upper="1e+16" velocity="0"/>
    <dynamics damping="0" friction="0"/>
  </joint>
  <link name="rotor_1">
    <inertial>
      <origin xyz="0 0 0"/>
      <mass value="1.5"/>
      <inertia ixx="9.75e-07" ixy="0" ixz="0" iyy="0.000273104" iyz="0" izz="0.000274004"/>
    </inertial>
    <collision name="rotor_1_collision">
      <geometry>
        <cylinder length="0.005" radius="0.128"/>
      </geometry>
    </collision>
    <visual name="rotor_1_visual">
      <geometry>
        <mesh filename="/home/byy/catkin_ws/src/livox_laser_simulation/meshes/iris_prop_ccw.dae" scale="1 1 1"/>
      </geometry>
    </visual>
  </link>
  <joint name="rotor_1_joint" type="revolute">
    <parent link="base_link"/>
    <child link="rotor_1"/>
    <origin rpy="0 0 0" xyz="-0.2 0.2 0.34"/>
    <axis xyz="0 0 1"/>
    <limit effort="0" lower="-1e+16" upper="1e+16" velocity="0"/>
    <dynamics damping="0" friction="0"/>
  </joint>
  <link name="rotor_2">
    <inertial>
      <origin xyz="0 0 0"/>
      <mass value="1.5"/>
      <inertia ixx="9.75e-07" ixy="0" ixz="0" iyy="0.000273104" iyz="0" izz="0.000274004"/>
    </inertial>
    <collision name="rotor_2_collision">
      <geometry>
        <cylinder length="0.005" radius="0.128"/>
      </geometry>
    </collision>
    <visual name="rotor_2_visual">
      <geometry>
        <mesh filename="/home/byy/catkin_ws/src/livox_laser_simulation/meshes/iris_prop_cw.dae" scale="1 1 1"/>
      </geometry>
    </visual>
  </link>
  <joint name="rotor_2_joint" type="revolute">
    <parent link="base_link"/>
    <child link="rotor_2"/>
    <origin rpy="0 0 0" xyz="0.2 0.2 0.34"/>
    <axis xyz="0 0 1"/>
    <limit effort="0" lower="-1e+16" upper="1e+16" velocity="0"/>
    <dynamics damping="0" friction="0"/>
  </joint>
  <link name="rotor_3">
    <inertial>
      <origin xyz="0 0 0"/>
      <mass value="1.5"/>
      <inertia ixx="9.75e-07" ixy="0" ixz="0" iyy="0.000273104" iyz="0" izz="0.000274004"/>
    </inertial>
    <collision name="rotor_3_collision">
      <geometry>
        <cylinder length="0.005" radius="0.128"/>
      </geometry>
    </collision>
    <visual name="rotor_3_visual">
      <geometry>
        <mesh filename="/home/byy/catkin_ws/src/livox_laser_simulation/meshes/iris_prop_cw.dae" scale="1 1 1"/>
      </geometry>
    </visual>
  </link>
  <joint name="rotor_3_joint" type="revolute">
    <parent link="base_link"/>
    <child link="rotor_3"/>
    <origin rpy="0 0 0" xyz="-0.2 -0.2 0.34"/>
    <axis xyz="0 0 1"/>
    <limit effort="0" lower="-1e+16" upper="1e+16" velocity="0"/>
    <dynamics damping="0" friction="0"/>
  </joint>
  <!-- Plugins -->
  <gazebo reference="base_link">
    <plugin filename="libgazebo_multirotor_base_plugin.so" name="rosbag">
      <robotNamespace/>
      <linkName>base_link</linkName>
      <rotorVelocitySlowdownSim>10</rotorVelocitySlowdownSim>
    </plugin>
  </gazebo>
  <gazebo reference="rotor_0">
    <plugin filename="libgazebo_motor_model.so" name="front_right_motor_model">
      <robotNamespace/>
      <jointName>rotor_0_joint</jointName>
      <linkName>rotor_0</linkName>
      <turningDirection>ccw</turningDirection>
      <timeConstantUp>0.0125</timeConstantUp>
      <timeConstantDown>0.025</timeConstantDown>
      <maxRotVelocity>1100</maxRotVelocity>
      <motorConstant>8.54858e-06</motorConstant>
      <momentConstant>0.06</momentConstant>
      <commandSubTopic>/gazebo/command/motor_speed</commandSubTopic>
      <motorNumber>0</motorNumber>
      <rotorDragCoefficient>0.000175</rotorDragCoefficient>
      <rollingMomentCoefficient>1e-06</rollingMomentCoefficient>
      <motorSpeedPubTopic>/motor_speed/0</motorSpeedPubTopic>
      <rotorVelocitySlowdownSim>10</rotorVelocitySlowdownSim>
    </plugin>
  </gazebo>
  <!-- Base Footprint -->
  <!--link name="base_link" /-->
  <!--xacro:LivoxMid360_IMU_Plantform/-->
  <joint name="mid360_imu_plantform_joint" type="fixed">
    <parent link="base_link"/>
    <child link="link_platform"/>
    <origin rpy="0.0 0.0 0.0" xyz="0.0 0.0 0.3367"/>
  </joint>
  <!-- link_platform -->
  <link name="link_platform">
    <visual>
      <geometry>
        <box size="0.15 0.1 0.1"/>
      </geometry>
    </visual>
    <collision>
      <geometry>
        <box size="0.15 0.1 0.1"/>
      </geometry>
    </collision>
    <inertial>
      <origin xyz="0 0 0"/>
      <mass value="1.5"/>
      <inertia ixx="0.1" ixy="0.0" ixz="0.0" iyy="0.1" iyz="0.0" izz="0.1"/>
    </inertial>
  </link>
  <gazebo reference="link_platform">
    <turnGravityOff>false</turnGravityOff>
  </gazebo>
  <joint name="lidar_platform_joint" type="fixed">
    <parent link="link_platform"/>
    <child link="livox_base"/>
    <origin rpy="0 0 0" xyz="0 0 0.06"/>
  </joint>
  <!--xacro:Livox_Mid40 name="livox"/-->
  <!--xacro:include filename="$(find livox_laser_simulation)/urdf/standardrobots_oasis300.xacro"/>
  <xacro:link_oasis name="oasis"/-->
  <link name="livox_base">
    <inertial>
      <mass value="0.1"/>
      <inertia ixx="0.01" ixy="0" ixz="0" iyy="0.01" iyz="0" izz="0.01"/>
    </inertial>
    <visual>
      <origin rpy="0 0 0" xyz="0.00 0 0.0"/>
      <geometry>
        <mesh filename="package://livox_laser_simulation/meshes/mid360.dae">
          </mesh>
      </geometry>
    </visual>
    <collision>
      <origin rpy="0 0 0" xyz="0 0 0"/>
      <geometry>
        <mesh filename="package://livox_laser_simulation/meshes/mid360_rules.dae"> 
		  </mesh>
      </geometry>
    </collision>
  </link>
  <link name="livox">
    <inertial>
      <mass value="0.1"/>
      <inertia ixx="0.01" ixy="0" ixz="0" iyy="0.01" iyz="0" izz="0.01"/>
    </inertial>
  </link>
  <joint name="livox_to_livox_base_joint" type="fixed">
    <parent link="livox_base"/>
    <child link="livox"/>
    <origin rpy="0 0 0" xyz="-0.012 0.0 0.047"/>
  </joint>
  <gazebo reference="livox">
    <sensor name="laser_livox" type="ray">
      <pose>0 0 0 0 0 0</pose>
      <visualize>True</visualize>
      <update_rate>10</update_rate>
      <!-- This ray plgin is only for visualization. -->
      <plugin filename="liblivox_laser_simulation.so" name="gazebo_ros_laser_controller">
        <ray>
          <scan>
            <horizontal>
              <samples>100</samples>
              <resolution>1</resolution>
              <min_angle>0</min_angle>
              <max_angle>6.28318</max_angle>
            </horizontal>
            <vertical>
              <samples>360</samples>
              <resolution>1</resolution>
              <min_angle>-0.0561995544444</min_angle>
              <max_angle>0.981223276667</max_angle>
            </vertical>
          </scan>
          <range>
            <min>0.1</min>
            <max>30</max>
            <resolution>0.02</resolution>
          </range>
          <noise>
            <type>gaussian</type>
            <mean>0.0</mean>
            <stddev>0.0</stddev>
          </noise>
        </ray>
        <visualize>True</visualize>
        <samples>24000</samples>
        <downsample>1</downsample>
        <csv_file_name>package://livox_laser_simulation/scan_mode/mid360.csv</csv_file_name>
        <ros_topic>scan</ros_topic>
      </plugin>
    </sensor>
  </gazebo>
  <!--imu -->
  <link name="imu_base_link">
    <visual>
      <origin rpy="0 0 0" xyz="0 0 0"/>
      <geometry>
        <box size="0.03 0.03 0.03"/>
      </geometry>
    </visual>
    <collision>
      <origin rpy="0 0 0" xyz="0 0 0"/>
      <geometry>
        <box size="0.03 0.03 0.03"/>
      </geometry>
    </collision>
    <inertial>
      <mass value="1.5"/>
      <inertia ixx="0.1" ixy="0.0" ixz="0.0" iyy="0.1" iyz="0.0" izz="0.1"/>
    </inertial>
  </link>
  <gazebo reference="imu_base_link">
    <material>Gazebo/Green</material>
    <turnGravityOff>false</turnGravityOff>
  </gazebo>
  <joint name="imu_platform_joint" type="fixed">
    <parent link="link_platform"/>
    <child link="imu_base_link"/>
    <origin rpy="0 0 0" xyz="0.05 0 0.065"/>
    <axis xyz="0 0 1"/>
  </joint>
  <gazebo reference="imu_base_link">
    <gravity>true</gravity>
    <sensor name="imu_sensor" type="imu">
      <always_on>true</always_on>
      <update_rate>200</update_rate>
      <visualize>true</visualize>
      <topic>/livox/imu</topic>
      <plugin filename="libgazebo_ros_imu_sensor.so" name="imu_plugin">
        <topicName>/livox/imu</topicName>
        <bodyName>imu_base_link</bodyName>
        <updateRateHZ>200.0</updateRateHZ>
        <gaussianNoise>0.00329</gaussianNoise>
        <xyzOffset>0 0 0</xyzOffset>
        <rpyOffset>0 0 0</rpyOffset>
        <frameName>imu_base_link</frameName>
      </plugin>
      <pose>0 0 0 0 0 0</pose>
    </sensor>
  </gazebo>
  <!--xacro:include filename="$(find livox_laser_simulation)/urdf/livox_mid360.xacro"/>
<xacro:Livox_Mid40 name="livox"/-->
  <!-- More plugins -->
</robot>

